2020-01-30 10:41:33,327 ERROR: Exception on /wot/jussi [GET] [in c:\users\mikoloth\ideaprojects\microblogmikko\venv\lib\site-packages\flask\app.py:1890]
Traceback (most recent call last):
  File "c:\users\mikoloth\ideaprojects\microblogmikko\venv\lib\site-packages\flask\app.py", line 2446, in wsgi_app
    response = self.full_dispatch_request()
  File "c:\users\mikoloth\ideaprojects\microblogmikko\venv\lib\site-packages\flask\app.py", line 1951, in full_dispatch_request
    rv = self.handle_user_exception(e)
  File "c:\users\mikoloth\ideaprojects\microblogmikko\venv\lib\site-packages\flask\app.py", line 1820, in handle_user_exception
    reraise(exc_type, exc_value, tb)
  File "c:\users\mikoloth\ideaprojects\microblogmikko\venv\lib\site-packages\flask\_compat.py", line 39, in reraise
    raise value
  File "c:\users\mikoloth\ideaprojects\microblogmikko\venv\lib\site-packages\flask\app.py", line 1949, in full_dispatch_request
    rv = self.dispatch_request()
  File "c:\users\mikoloth\ideaprojects\microblogmikko\venv\lib\site-packages\flask\app.py", line 1935, in dispatch_request
    return self.view_functions[rule.endpoint](**req.view_args)
  File "c:\users\mikoloth\ideaprojects\microblogmikko\venv\lib\site-packages\flask_login\utils.py", line 261, in decorated_view
    return func(*args, **kwargs)
  File "C:\Users\Mikoloth\IdeaProjects\microblogmikko\app\wot\routes.py", line 24, in user
    return render_template('wot.html', user=user, nickdata=nickdata)
  File "c:\users\mikoloth\ideaprojects\microblogmikko\venv\lib\site-packages\flask\templating.py", line 138, in render_template
    ctx.app.jinja_env.get_or_select_template(template_name_or_list),
  File "c:\users\mikoloth\ideaprojects\microblogmikko\venv\lib\site-packages\jinja2\environment.py", line 930, in get_or_select_template
    return self.get_template(template_name_or_list, parent, globals)
  File "c:\users\mikoloth\ideaprojects\microblogmikko\venv\lib\site-packages\jinja2\environment.py", line 883, in get_template
    return self._load_template(name, self.make_globals(globals))
  File "c:\users\mikoloth\ideaprojects\microblogmikko\venv\lib\site-packages\jinja2\environment.py", line 857, in _load_template
    template = self.loader.load(self, name, globals)
  File "c:\users\mikoloth\ideaprojects\microblogmikko\venv\lib\site-packages\jinja2\loaders.py", line 117, in load
    source, filename, uptodate = self.get_source(environment, name)
  File "c:\users\mikoloth\ideaprojects\microblogmikko\venv\lib\site-packages\flask\templating.py", line 60, in get_source
    return self._get_source_fast(environment, template)
  File "c:\users\mikoloth\ideaprojects\microblogmikko\venv\lib\site-packages\flask\templating.py", line 89, in _get_source_fast
    raise TemplateNotFound(template)
jinja2.exceptions.TemplateNotFound: wot.html
2020-01-30 10:44:11,588 INFO: Microblog startup [in C:\Users\Mikoloth\IdeaProjects\microblogmikko\app\__init__.py:83]
2020-01-30 14:31:27,347 INFO: Microblog startup [in C:\Users\Mikoloth\IdeaProjects\microblogmikko\app\__init__.py:83]
2020-01-30 14:31:45,911 INFO: Microblog startup [in C:\Users\Mikoloth\IdeaProjects\microblogmikko\app\__init__.py:83]
2020-01-30 14:32:07,520 INFO: Microblog startup [in C:\Users\Mikoloth\IdeaProjects\microblogmikko\app\__init__.py:83]
2020-01-30 14:32:41,850 ERROR: Exception on /edit_profile [POST] [in c:\users\mikoloth\ideaprojects\microblogmikko\venv\lib\site-packages\flask\app.py:1890]
Traceback (most recent call last):
  File "c:\users\mikoloth\ideaprojects\microblogmikko\venv\lib\site-packages\flask\app.py", line 2446, in wsgi_app
    response = self.full_dispatch_request()
  File "c:\users\mikoloth\ideaprojects\microblogmikko\venv\lib\site-packages\flask\app.py", line 1951, in full_dispatch_request
    rv = self.handle_user_exception(e)
  File "c:\users\mikoloth\ideaprojects\microblogmikko\venv\lib\site-packages\flask\app.py", line 1820, in handle_user_exception
    reraise(exc_type, exc_value, tb)
  File "c:\users\mikoloth\ideaprojects\microblogmikko\venv\lib\site-packages\flask\_compat.py", line 39, in reraise
    raise value
  File "c:\users\mikoloth\ideaprojects\microblogmikko\venv\lib\site-packages\flask\app.py", line 1949, in full_dispatch_request
    rv = self.dispatch_request()
  File "c:\users\mikoloth\ideaprojects\microblogmikko\venv\lib\site-packages\flask\app.py", line 1935, in dispatch_request
    return self.view_functions[rule.endpoint](**req.view_args)
  File "c:\users\mikoloth\ideaprojects\microblogmikko\venv\lib\site-packages\flask_login\utils.py", line 261, in decorated_view
    return func(*args, **kwargs)
  File "C:\Users\Mikoloth\IdeaProjects\microblogmikko\app\main\routes.py", line 97, in edit_profile
    current_user.set_wotid(form.wotid.data)
  File "C:\Users\Mikoloth\IdeaProjects\microblogmikko\app\models.py", line 121, in set_wotid
    json_url = urlopen("https://api.worldoftanks.eu/wot/account/list/?application_id="+os.environ['WOT_API_KEY']+"&search="+nick)
NameError: name 'urlopen' is not defined
2020-01-30 14:37:07,856 INFO: Microblog startup [in C:\Users\Mikoloth\IdeaProjects\microblogmikko\app\__init__.py:83]
2020-01-30 14:37:27,946 ERROR: Exception on /edit_profile [POST] [in c:\users\mikoloth\ideaprojects\microblogmikko\venv\lib\site-packages\flask\app.py:1890]
Traceback (most recent call last):
  File "c:\users\mikoloth\ideaprojects\microblogmikko\venv\lib\site-packages\flask\app.py", line 2446, in wsgi_app
    response = self.full_dispatch_request()
  File "c:\users\mikoloth\ideaprojects\microblogmikko\venv\lib\site-packages\flask\app.py", line 1951, in full_dispatch_request
    rv = self.handle_user_exception(e)
  File "c:\users\mikoloth\ideaprojects\microblogmikko\venv\lib\site-packages\flask\app.py", line 1820, in handle_user_exception
    reraise(exc_type, exc_value, tb)
  File "c:\users\mikoloth\ideaprojects\microblogmikko\venv\lib\site-packages\flask\_compat.py", line 39, in reraise
    raise value
  File "c:\users\mikoloth\ideaprojects\microblogmikko\venv\lib\site-packages\flask\app.py", line 1949, in full_dispatch_request
    rv = self.dispatch_request()
  File "c:\users\mikoloth\ideaprojects\microblogmikko\venv\lib\site-packages\flask\app.py", line 1935, in dispatch_request
    return self.view_functions[rule.endpoint](**req.view_args)
  File "c:\users\mikoloth\ideaprojects\microblogmikko\venv\lib\site-packages\flask_login\utils.py", line 261, in decorated_view
    return func(*args, **kwargs)
  File "C:\Users\Mikoloth\IdeaProjects\microblogmikko\app\main\routes.py", line 97, in edit_profile
    current_user.set_wotid(form.wotid.data)
  File "C:\Users\Mikoloth\IdeaProjects\microblogmikko\app\models.py", line 123, in set_wotid
    flash(data["data"])
NameError: name 'flash' is not defined
2020-01-30 14:40:41,256 INFO: Microblog startup [in C:\Users\Mikoloth\IdeaProjects\microblogmikko\app\__init__.py:83]
2020-01-30 14:42:36,331 INFO: Microblog startup [in C:\Users\Mikoloth\IdeaProjects\microblogmikko\app\__init__.py:83]
2020-01-30 14:43:00,908 ERROR: Exception on /edit_profile [POST] [in c:\users\mikoloth\ideaprojects\microblogmikko\venv\lib\site-packages\flask\app.py:1890]
Traceback (most recent call last):
  File "c:\users\mikoloth\ideaprojects\microblogmikko\venv\lib\site-packages\flask\app.py", line 2446, in wsgi_app
    response = self.full_dispatch_request()
  File "c:\users\mikoloth\ideaprojects\microblogmikko\venv\lib\site-packages\flask\app.py", line 1951, in full_dispatch_request
    rv = self.handle_user_exception(e)
  File "c:\users\mikoloth\ideaprojects\microblogmikko\venv\lib\site-packages\flask\app.py", line 1820, in handle_user_exception
    reraise(exc_type, exc_value, tb)
  File "c:\users\mikoloth\ideaprojects\microblogmikko\venv\lib\site-packages\flask\_compat.py", line 39, in reraise
    raise value
  File "c:\users\mikoloth\ideaprojects\microblogmikko\venv\lib\site-packages\flask\app.py", line 1949, in full_dispatch_request
    rv = self.dispatch_request()
  File "c:\users\mikoloth\ideaprojects\microblogmikko\venv\lib\site-packages\flask\app.py", line 1935, in dispatch_request
    return self.view_functions[rule.endpoint](**req.view_args)
  File "c:\users\mikoloth\ideaprojects\microblogmikko\venv\lib\site-packages\flask_login\utils.py", line 261, in decorated_view
    return func(*args, **kwargs)
  File "C:\Users\Mikoloth\IdeaProjects\microblogmikko\app\main\routes.py", line 97, in edit_profile
    current_user.set_wotid(form.wotid.data)
  File "C:\Users\Mikoloth\IdeaProjects\microblogmikko\app\models.py", line 123, in set_wotid
    flash(data["data"]["account_id"])
TypeError: list indices must be integers or slices, not str
2020-01-30 14:59:51,964 INFO: Microblog startup [in C:\Users\Mikoloth\IdeaProjects\microblogmikko\app\__init__.py:83]
